Workbook

Sheet Instruções
A1: Legenda | B1: Células amarelas: preencher. Células cinzas: calculadas (não editar). Coluna Conferência (vermelho): inconsistências a resolver. Linha cinza em itálico no Roteiro: exemplo. Protocolo completo: docs/pesquisa/estudo2_tarefas.md.
A2: Condições | B2: S = Chrome sem extensão (perfil S). C = Chrome com Accessify v1.1.0-jis_submission (perfil C), acionado pelo painel lateral em cada página nova do site da tarefa, antes de procurar a informação: Alt+Shift+A (abre o painel e inicia a análise), ouvir o resultado, "Aplicar Otimizações", ouvir a confirmação e voltar à página. A sequência exata de teclas (provavelmente F6 para alternar painel e página) é fixada no piloto. Não acionar duas vezes na mesma página (a segunda análise recarrega a página). Sites externos ao da tarefa não recebem o Accessify.
A3: Tempos | B3: t0 = o(a) facilitador(a) diz "pode começar". t1 = a avaliadora diz a resposta final ("minha resposta é…") ou "desisto"; se ela corrigir a resposta, valem a última resposta e o seu t1. Releituras da instrução a pedido ficam dentro do tempo e são contadas em Repetições. Tempo total = t1 − t0. Tempo no painel (só em C) = soma dos intervalos entre Alt+Shift+A e a volta do foco à página (primeira fala do NVDA vinda da página depois da confirmação). Tempo líquido = total − painel.
A4: Teto | B4: 300 s de tempo líquido nas duas condições. Ao vivo, o(a) facilitador(a) pausa o cronômetro durante o painel e encerra a tarefa aos 300 s; execução encerrada pelo(a) facilitador(a) ou com tempo líquido acima de 300 s conta como F.
A5: Resultado | B5: S = resposta correta segundo o critério da linha, sem ajuda, dentro do teto. P = parcialmente correta, como definido no critério. F = errada, desistência, ajuda ou teto. Ajuda = indicar caminho, conteúdo ou atalho. Lembrar de acionar o Accessify não é ajuda: o(a) facilitador(a) lembra assim que ela começar a explorar uma página nova sem o painel, e conta em "Lembretes".
A6: Falha da extensão | B6: Se o painel mostrar erro ou não anunciar o fim da análise em 60 s, a avaliadora segue sem acionar de novo; escrever "C degradada" em Observações (entra numa análise de sensibilidade).
A7: SEQ (Single Ease Question) | B7: Logo após cada tarefa: "No geral, quão fácil ou difícil foi esta tarefa, de 1 (muito difícil) a 7 (muito fácil)?"
A8: Estratégia | B8: Como a avaliadora chegou à resposta: cabeçalhos, lista de links, busca do NVDA, leitura linear, tabela, menu do site, busca do site ou várias (texto livre permitido).
A9: Barreiras e falas do NVDA | B9: Trecho literal do que o NVDA falou nos pontos de dificuldade (ex.: "link Abrir link 11", "gráfico"), com o tempo no vídeo. Alimenta o Barrier Walkthrough (impacto 1–3 × persistência).
A10: Antes de cada tarefa | B10: O(a) facilitador(a) abre a URL inicial, espera a carga, cala o NVDA (Ctrl) e só então lê a ação; a avaliadora não toca no teclado até "pode começar". Sem pensar em voz alta (comentários depois da resposta), sem ensinar atalhos, sem baixar arquivos.

Sheet Sessão
A1: Dados da sessão (preencher antes de começar)
A3: Data e local
A4: Avaliadora
A5: Facilitador(a)
A6: Codificador(a) 1 / 2
A7: Versão do NVDA
A8: NVDA: voz e velocidade
A9: NVDA: anunciar cabeçalhos de linha/coluna de tabela
A10: NVDA: ler automaticamente a página ao carregar
A11: NVDA: nível de log (Entrada/saída) e arquivo do log
A12: Versão do Chrome
A13: Perfil S (sem extensão) / Perfil C (com extensão)
A14: Build da extensão | B14: v1.1.0-jis_submission (informar o commit)
A15: Provedor e modelo | B15: Ollama local, qwen3:8b, raciocínio original (padrão da v1.1.0)
A16: Máquina do Ollama e latência medida no piloto
A17: Modo da condição C | B17: painel lateral em cada página (recomendado) / modo automático
A18: Sequência de teclas do painel fixada no piloto
A19: Janela, zoom e largura útil da página com o painel aberto | B19: maximizada (≥ 1280 px), zoom 100%
A20: Fontes de áudio gravadas (sistema/NVDA e microfone)
A21: Conferência das respostas (eval/tools/estudo2_conferir.py): data, hora e resultado
A22: Arquivo da gravação (OBS)
A23: Tarefas trocadas por reserva (e motivo)
A25: Familiaridade prévia da avaliadora com cada site
A26: SOL — anais e busca (sol.sbc.org.br)
A27: SOL Livros (books-sol.sbc.org.br)
A28: Portal de Periódicos CAPES
A29: Site da CAPES (gov.br/capes)
A30: Site do IHC (2025/2026)
A31: Site do CSBC 2026
A32: Site do EduComp 2026
... A34: Journal on Interactive Systems (JIS)

Sheet Roteiro
A1: Estudo 2 — Roteiro e registro das tarefas (uma linha por execução)
A2: Preencher só as células amarelas, a partir do vídeo e do log do NVDA; as cinzas são calculadas e a coluna Conferência aponta inconsistências. Tempos do vídeo como mm:ss ou h:mm:ss. Condição: S = sem extensão, C = com Accessify v1.1.0. Definições na aba Instruções. A linha 4 é um exemplo e não entra no Resumo.
A3: Ordem | B3: Bloco | C3: Condição | D3: Tarefa | E3: Variante | F3: Site | G3: URL inicial | H3: Ação (ler em voz alta) | I3: Saída esperada | J3: Critério de sucesso | K3: Estimativa (s) | L3: Resposta dada | M3: Resultado (S/P/F) | N3: t0 no vídeo (mm:ss) | O3: t1 no vídeo (mm:ss) | P3: t0 (s) | Q3: t1 (s) | R3: Tempo total (s) | S3: Tempo no painel (s) | T3: Tempo líquido (s) | U3: Acima do teto (300 s líquidos)? | V3: Encerrada pelo(a) facilitador(a) (s/n) | W3: Repetições da instrução | X3: Lembretes para acionar o Accessify | Y3: Ajuda (sim → F) | Z3: SEQ (1–7) | AA3: Estratégia | AB3: Barreiras e falas do NVDA | AC3: Observações | AD3: Conferência | AE3: Chave
A4: ex. | B4: EXEMPLO (não conta) | C4: — | D4: IHC-2 | E4: A | F4: IHC 2026 — Programação Geral | G4: https://ihc.sbc.org.br/2026/index.php/programacao/ | H4: Na página de programação do IHC 2026, sem baixar arquivos, descubra qual sessão técnica aconteceu na terça-feira, 20 de outubro, às 10h30. | I4: Sessão Técnica 2 — Diversidade e Justiça Social (Sala Juazeiro, 10h30–12h) | J4: S: número (2) ou tema (Diversidade e Justiça Social). P: lê a linha certa, mas não diz qual é a sessão técnica. F: outro dia (a aba de segunda abre por padrão), outra linha, desistência. | K4: 70 | L4: Sessão técnica 2, Diversidade e Justiça Social | M4: S | N4: 12:05 | O4: 13:21 | P4: =IF(N4="","",IF(LEN(N4)-LEN(SUBSTITUTE(N4,":",""))=2,LEFT(N4,FIND(":",N4)-1)*3600+MID(N4,FIND(":",N4)+1,2)*60+RIGHT(N4,2),LEFT(N4,FIND(":",N4)-1)*60+RIGHT(N4,2))) -> 725 | Q4: =IF(O4="","",IF(LEN(O4)-LEN(SUBSTITUTE(O4,":",""))=2,LEFT(O4,FIND(":",O4)-1)*3600+MID(O4,FIND(":",O4)+1,2)*60+RIGHT(O4,2),LEFT(O4,FIND(":",O4)-1)*60+RIGHT(O4,2))) -> 801 | R4: =IF(OR(P4="",Q4=""),"",Q4-P4) -> 76 | S4: 0 | T4: =IF(R4="","",IF(AND(S4<>"",NOT(ISNUMBER(S4))),"painel inválido",R4-N(S4))) -> 76 | U4: =IF(NOT(ISNUMBER(T4)),"",IF(T4>300,"sim","não")) -> não | V4: n | W4: 0 | X4: 0 | Y4: não | Z4: 6 | AA4: várias | AB4: 12:31 buscou "10h30" com a aba de segunda aberta e caiu na linha errada; voltou e ativou a aba "20/10 - Terça". | AC4: Usou Ctrl+Alt+setas na tabela. | AD4: =TRIM(IF(AND(ISNUMBER(R4),R4<=0),"t1 não é depois de t0; ","")&IF(AND(C4="C",ISNUMBER(R4),S4=""),"falta o tempo no painel; ","")&IF(AND(U4="sim",M4<>"F"),"acima do teto: deve ser F; ","")&IF(AND(V4="s",M4<>"F"),"encerrada: deve ser F; ","")&IF(AND(Y4="sim",M4<>"F"),"houve ajuda: deve ser F; ","")&IF(AND(M4<>"",ISNUMBER(R4)=FALSE()),"falta t0 ou t1; ","")) | AE4: =D4&"|"&C4 -> IHC-2|—
A5: Sessão 1 · Preparação e regras (15 min); familiarização livre no perfil S (2 min) · Bloco 1a — grupo G1, SEM extensão (perfil S), variante A
A6: 1 | B6: Sessão 1 · Bloco 1a | C6: S | D6: SOL-1 | E6: A | F6: SOL — busca integrada | G6: https://sol.sbc.org.br/busca/ | H6: Na busca da biblioteca digital da SBC, a SOL, procure nos Anais de Eventos o artigo "Can AI Judge Usability? A Comparative Analysis of Generative Tools on Climate Conference Websites" e diga o nome do primeiro autor. | I6: Danilo Teixeira Lima (no resultado deve aparecer como "Lima, Danilo Teixeira"; confirmar no piloto) | J6: S: "Danilo Teixeira Lima", "Danilo Lima" ou "Lima". P: chega ao resultado certo, mas diz outro autor do artigo. F: não consegue enviar a busca (a base "Anais de Eventos" é obrigatória e o aviso é só visual), outro nome, desistência. | K6: 105 | P6: =IF(N6="","",IF(LEN(N6)-LEN(SUBSTITUTE(N6,":",""))=2,LEFT(N6,FIND(":",N6)-1)*3600+MID(N6,FIND(":",N6)+1,2)*60+RIGHT(N6,2),LEFT(N6,FIND(":",N6)-1)*60+RIGHT(N6,2))) | Q6: =IF(O6="","",IF(LEN(O6)-LEN(SUBSTITUTE(O6,":",""))=2,LEFT(O6,FIND(":",O6)-1)*3600+MID(O6,FIND(":",O6)+1,2)*60+RIGHT(O6,2),LEFT(O6,FIND(":",O6)-1)*60+RIGHT(O6,2))) | R6: =IF(OR(P6="",Q6=""),"",Q6-P6) | T6: =IF(R6="","",IF(AND(S6<>"",NOT(ISNUMBER(S6))),"painel inválido",R6-N(S6))) | U6: =IF(NOT(ISNUMBER(T6)),"",IF(T6>300,"sim","não")) | AD6: =TRIM(IF(AND(ISNUMBER(R6),R6<=0),"t1 não é depois de t0; ","")&IF(AND(C6="C",ISNUMBER(R6),S6=""),"falta o tempo no painel; ","")&IF(AND(U6="sim",M6<>"F"),"acima do teto: deve ser F; ","")&IF(AND(V6="s",M6<>"F"),"encerrada: deve ser F; ","")&IF(AND(Y6="sim",M6<>"F"),"houve ajuda: deve ser F; ","")&IF(AND(M6<>"",ISNUMBER(R6)=FALSE()),"falta t0 ou t1; ","")) | AE6: =D6&"|"&C6 -> SOL-1|S
A7: 2 | B7: Sessão 1 · Bloco 1a | C7: S | D7: CAPES-1 | E7: A | F7: Portal de Periódicos CAPES — Lista A–Z | G7: https://www.periodicos.capes.gov.br/index.php/acervo/lista-a-z-periodicos.html | H7: No Portal de Periódicos da CAPES, descubra qual é o ISSN do periódico Journal of the Brazilian Computer Society. | I7: 0104-6500 | J7: S: 0104-6500 (hífen opcional). P: chegou à página do periódico sem ler o ISSN, ou deu um ISSN lido fora do Portal (SciELO). F: ISSN de outro título, desistência. | K7: 90 | P7: =IF(N7="","",IF(LEN(N7)-LEN(SUBSTITUTE(N7,":",""))=2,LEFT(N7,FIND(":",N7)-1)*3600+MID(N7,FIND(":",N7)+1,2)*60+RIGHT(N7,2),LEFT(N7,FIND(":",N7)-1)*60+RIGHT(N7,2))) | Q7: =IF(O7="","",IF(LEN(O7)-LEN(SUBSTITUTE(O7,":",""))=2,LEFT(O7,FIND(":",O7)-1)*3600+MID(O7,FIND(":",O7)+1,2)*60+RIGHT(O7,2),LEFT(O7,FIND(":",O7)-1)*60+RIGHT(O7,2))) | R7: =IF(OR(P7="",Q7=""),"",Q7-P7) | T7: =IF(R7="","",IF(AND(S7<>"",NOT(ISNUMBER(S7))),"painel inválido",R7-N(S7))) | U7: =IF(NOT(ISNUMBER(T7)),"",IF(T7>300,"sim","não")) | AD7: =TRIM(IF(AND(ISNUMBER(R7),R7<=0),"t1 não é depois de t0; ","")&IF(AND(C7="C",ISNUMBER(R7),S7=""),"falta o tempo no painel; ","")&IF(AND(U7="sim",M7<>"F"),"acima do teto: deve ser F; ","")&IF(AND(V7="s",M7<>"F"),"encerrada: deve ser F; ","")&IF(AND(Y7="sim",M7<>"F"),"houve ajuda: deve ser F; ","")&IF(AND(M7<>"",ISNUMBER(R7)=FALSE()),"falta t0 ou t1; ","")) | AE7: =D7&"|"&C7 -> CAPES-1|S
A8: 3 | B8: Sessão 1 · Bloco 1a | C8: S | D8: IHC-2 | E8: A | F8: IHC 2026 — Programação Geral | G8: https://ihc.sbc.org.br/2026/index.php/programacao/ | H8: Na página de programação do IHC 2026, sem baixar arquivos, descubra qual sessão técnica aconteceu na terça-feira, 20 de outubro, às 10h30. | I8: Sessão Técnica 2 — Diversidade e Justiça Social (Sala Juazeiro, 10h30–12h) | J8: S: número (2) ou tema (Diversidade e Justiça Social). P: lê a linha certa, mas não diz qual é a sessão técnica. F: outro dia (a aba de segunda abre por padrão), outra linha, desistência. | K8: 70 | P8: =IF(N8="","",IF(LEN(N8)-LEN(SUBSTITUTE(N8,":",""))=2,LEFT(N8,FIND(":",N8)-1)*3600+MID(N8,FIND(":",N8)+1,2)*60+RIGHT(N8,2),LEFT(N8,FIND(":",N8)-1)*60+RIGHT(N8,2))) | Q8: =IF(O8="","",IF(LEN(O8)-LEN(SUBSTITUTE(O8,":",""))=2,LEFT(O8,FIND(":",O8)-1)*3600+MID(O8,FIND(":",O8)+1,2)*60+RIGHT(O8,2),LEFT(O8,FIND(":",O8)-1)*60+RIGHT(O8,2))) | R8: =IF(OR(P8="",Q8=""),"",Q8-P8) | T8: =IF(R8="","",IF(AND(S8<>"",NOT(ISNUMBER(S8))),"painel inválido",R8-N(S8))) | U8: =IF(NOT(ISNUMBER(T8)),"",IF(T8>300,"sim","não")) | AD8: =TRIM(IF(AND(ISNUMBER(R8),R8<=0),"t1 não é depois de t0; ","")&IF(AND(C8="C",ISNUMBER(R8),S8=""),"falta o tempo no painel; ","")&IF(AND(U8="sim",M8<>"F"),"acima do teto: deve ser F; ","")&IF(AND(V8="s",M8<>"F"),"encerrada: deve ser F; ","")&IF(AND(Y8="sim",M8<>"F"),"houve ajuda: deve ser F; ","")&IF(AND(M8<>"",ISNUMBER(R8)=FALSE()),"falta t0 ou t1; ","")) | AE8: =D8&"|"&C8 -> IHC-2|S
A9: 4 | B9: Sessão 1 · Bloco 1a | C9: S | D9: CSBC-2 | E9: A | F9: CSBC 2026 — rodapé de patrocinadores | G9: https://csbc.sbc.org.br/2026/ | H9: No site do CSBC 2026, o Congresso da SBC, descubra qual empresa é a patrocinadora da categoria Cobre. | I9: Scherm (aceitar scherm.com.br, em qualquer pronúncia ou soletrado) | J9: S: "Scherm" ou o domínio. P: chega ao link da categoria Cobre, mas não consegue nomear a empresa. F: empresa de outra categoria, desistência. | K9: 50 | P9: =IF(N9="","",IF(LEN(N9)-LEN(SUBSTITUTE(N9,":",""))=2,LEFT(N9,FIND(":",N9)-1)*3600+MID(N9,FIND(":",N9)+1,2)*60+RIGHT(N9,2),LEFT(N9,FIND(":",N9)-1)*60+RIGHT(N9,2))) | Q9: =IF(O9="","",IF(LEN(O9)-LEN(SUBSTITUTE(O9,":",""))=2,LEFT(O9,FIND(":",O9)-1)*3600+MID(O9,FIND(":",O9)+1,2)*60+RIGHT(O9,2),LEFT(O9,FIND(":",O9)-1)*60+RIGHT(O9,2))) | R9: =IF(OR(P9="",Q9=""),"",Q9-P9) | T9: =IF(R9="","",IF(AND(S9<>"",NOT(ISNUMBER(S9))),"painel inválido",R9-N(S9))) | U9: =IF(NOT(ISNUMBER(T9)),"",IF(T9>300,"sim","não")) | AD9: =TRIM(IF(AND(ISNUMBER(R9),R9<=0),"t1 não é depois de t0; ","")&IF(AND(C9="C",ISNUMBER(R9),S9=""),"falta o tempo no painel; ","")&IF(AND(U9="sim",M9<>"F"),"acima do teto: deve ser F; ","")&IF(AND(V9="s",M9<>"F"),"encerrada: deve ser F; ","")&IF(AND(Y9="sim",M9<>"F"),"houve ajuda: deve ser F; ","")&IF(AND(M9<>"",ISNUMBER(R9)=FALSE()),"falta t0 ou t1; ","")) | AE9: =D9&"|"&C9 -> CSBC-2|S
A10: Trocar para o perfil C · P0, treino do painel · Bloco 1b — grupo G2, COM extensão, variante A
A11: 0 | B11: Sessão 1 · P0 (treino) | C11: Painel | D11: P0 | E11: — | F11: W3C BAD (controle do Estudo 1) | G11: https://www.w3.org/WAI/demos/bad/before/home.html | H11: Com o Accessify, analise esta página, aplique as otimizações e volte para a página. Avise quando estiver de volta. | I11: Painel anuncia que as otimizações foram aplicadas; o foco volta à página | J11: S: aciona Alt+Shift+A, chega ao painel, ouve o resultado da análise, ativa "Aplicar Otimizações", ouve a confirmação e volta à página, sem ajuda. P: conclui com uma dica. F: não conclui. (Treino: a dica é permitida, mas registrada.) | K11: 90 | P11: =IF(N11="","",IF(LEN(N11)-LEN(SUBSTITUTE(N11,":",""))=2,LEFT(N11,FIND(":",N11)-1)*3600+MID(N11,FIND(":",N11)+1,2)*60+RIGHT(N11,2),LEFT(N11,FIND(":",N11)-1)*60+RIGHT(N11,2))) | Q11: =IF(O11="","",IF(LEN(O11)-LEN(SUBSTITUTE(O11,":",""))=2,LEFT(O11,FIND(":",O11)-1)*3600+MID(O11,FIND(":",O11)+1,2)*60+RIGHT(O11,2),LEFT(O11,FIND(":",O11)-1)*60+RIGHT(O11,2))) | R11: =IF(OR(P11="",Q11=""),"",Q11-P11) | T11: =IF(R11="","",IF(AND(S11<>"",NOT(ISNUMBER(S11))),"painel inválido",R11-N(S11))) | U11: =IF(NOT(ISNUMBER(T11)),"",IF(T11>300,"sim","não")) | AD11: =TRIM(IF(AND(ISNUMBER(R11),R11<=0),"t1 não é depois de t0; ","")&IF(AND(C11="C",ISNUMBER(R11),S11=""),"falta o tempo no painel; ","")&IF(AND(U11="sim",M11<>"F"),"acima do teto: deve ser F; ","")&IF(AND(V11="s",M11<>"F"),"encerrada: deve ser F; ","")&IF(AND(Y11="sim",M11<>"F"),"houve ajuda: deve ser F; ","")&IF(AND(M11<>"",ISNUMBER(R11)=FALSE()),"falta t0 ou t1; ","")) | AE11: =D11&"|"&C11 -> P0|Painel
A12: 5 | B12: Sessão 1 · Bloco 1b | C12: C | D12: SOL-2 | E12: A | F12: SOL — anais do IHC 2025 | G12: https://sol.sbc.org.br/index.php/ihc/issue/view/1582 | H12: Nos anais do IHC 2025, na SOL, diga em qual trilha foi publicado o artigo "Falando, desenhando e avaliando: workshops para a construção de um repositório sobre tecnologias para pessoas idosas". | I12: Relatos de Experiência | J12: S: "Relatos de Experiência" (com ou sem "Trilha"). P: chega ao artigo, mas não identifica a trilha. F: outra trilha (Abertura, Ideias Inovadoras, Prêmio, Artigos de Pesquisa), desistência. | K12: 65 | P12: =IF(N12="","",IF(LEN(N12)-LEN(SUBSTITUTE(N12,":",""))=2,LEFT(N12,FIND(":",N12)-1)*3600+MID(N12,FIND(":",N12)+1,2)*60+RIGHT(N12,2),LEFT(N12,FIND(":",N12)-1)*60+RIGHT(N12,2))) | Q12: =IF(O12="","",IF(LEN(O12)-LEN(SUBSTITUTE(O12,":",""))=2,LEFT(O12,FIND(":",O12)-1)*3600+MID(O12,FIND(":",O12)+1,2)*60+RIGHT(O12,2),LEFT(O12,FIND(":",O12)-1)*60+RIGHT(O12,2))) | R12: =IF(OR(P12="",Q12=""),"",Q12-P12) | T12: =IF(R12="","",IF(AND(S12<>"",NOT(ISNUMBER(S12))),"painel inválido",R12-N(S12))) | U12: =IF(NOT(ISNUMBER(T12)),"",IF(T12>300,"sim","não")) | AD12: =TRIM(IF(AND(ISNUMBER(R12),R12<=0),"t1 não é depois de t0; ","")&IF(AND(C12="C",ISNUMBER(R12),S12=""),"falta o tempo no painel; ","")&IF(AND(U12="sim",M12<>"F"),"acima do teto: deve ser F; ","")&IF(AND(V12="s",M12<>"F"),"encerrada: deve ser F; ","")&IF(AND(Y12="sim",M12<>"F"),"houve ajuda: deve ser F; ","")&IF(AND(M12<>"",ISNUMBER(R12)=FALSE()),"falta t0 ou t1; ","")) | AE12: =D12&"|"&C12 -> SOL-2|C
A13: 6 | B13: Sessão 1 · Bloco 1b | C13: C | D13: CAPES-2 | E13: A | F13: Portal de Periódicos CAPES — Suporte regional | G13: https://www.periodicos.capes.gov.br/index.php/ajuda/suporte-regional.html | H13: No Portal de Periódicos da CAPES, encontre o e-mail de contato do suporte regional para a região Centro-Oeste. | I13: lucianasetubal@unb.br ou seanio.avelino@unb.br (qualquer um) | J13: S: um dos dois e-mails @unb.br. P: abre a região Centro-Oeste, mas dá só o nome ou o telefone, ou soletra o e-mail com 1 caractere errado. F: e-mail de outra região, desistência. | K13: 130 | P13: =IF(N13="","",IF(LEN(N13)-LEN(SUBSTITUTE(N13,":",""))=2,LEFT(N13,FIND(":",N13)-1)*3600+MID(N13,FIND(":",N13)+1,2)*60+RIGHT(N13,2),LEFT(N13,FIND(":",N13)-1)*60+RIGHT(N13,2))) | Q13: =IF(O13="","",IF(LEN(O13)-LEN(SUBSTITUTE(O13,":",""))=2,LEFT(O13,FIND(":",O13)-1)*3600+MID(O13,FIND(":",O13)+1,2)*60+RIGHT(O13,2),LEFT(O13,FIND(":",O13)-1)*60+RIGHT(O13,2))) | R13: =IF(OR(P13="",Q13=""),"",Q13-P13) | T13: =IF(R13="","",IF(AND(S13<>"",NOT(ISNUMBER(S13))),"painel inválido",R13-N(S13))) | U13: =IF(NOT(ISNUMBER(T13)),"",IF(T13>300,"sim","não")) | AD13: =TRIM(IF(AND(ISNUMBER(R13),R13<=0),"t1 não é depois de t0; ","")&IF(AND(C13="C",ISNUMBER(R13),S13=""),"falta o tempo no painel; ","")&IF(AND(U13="sim",M13<>"F"),"acima do teto: deve ser F; ","")&IF(AND(V13="s",M13<>"F"),"encerrada: deve ser F; ","")&IF(AND(Y13="sim",M13<>"F"),"houve ajuda: deve ser F; ","")&IF(AND(M13<>"",ISNUMBER(R13)=FALSE()),"falta t0 ou t1; ","")) | AE13: =D13&"|"&C13 -> CAPES-2|C
A14: 7 | B14: Sessão 1 · Bloco 1b | C14: C | D14: IHC-1 | E14: A | F14: IHC 2026 — Sessões Técnicas | G14: https://ihc.sbc.org.br/2026/ | H14: No site do IHC 2026, sem baixar arquivos, descubra em que dia, horário e sala foi apresentado o artigo "Explorando lacunas e oportunidades em aplicativos móveis para suporte ao luto com aplicabilidade profissional". | I14: Quinta-feira, 22/10, das 08h30 às 10h00, sala Algaroba (Sessão Técnica 10) | J14: S: dia (quinta ou 22/10) + início 08h30 + sala Algaroba. P: 2 dos 3 dados, ou só a sessão certa. F: dados de outra sessão, desistência. | K14: 165 | P14: =IF(N14="","",IF(LEN(N14)-LEN(SUBSTITUTE(N14,":",""))=2,LEFT(N14,FIND(":",N14)-1)*3600+MID(N14,FIND(":",N14)+1,2)*60+RIGHT(N14,2),LEFT(N14,FIND(":",N14)-1)*60+RIGHT(N14,2))) | Q14: =IF(O14="","",IF(LEN(O14)-LEN(SUBSTITUTE(O14,":",""))=2,LEFT(O14,FIND(":",O14)-1)*3600+MID(O14,FIND(":",O14)+1,2)*60+RIGHT(O14,2),LEFT(O14,FIND(":",O14)-1)*60+RIGHT(O14,2))) | R14: =IF(OR(P14="",Q14=""),"",Q14-P14) | T14: =IF(R14="","",IF(AND(S14<>"",NOT(ISNUMBER(S14))),"painel inválido",R14-N(S14))) | U14: =IF(NOT(ISNUMBER(T14)),"",IF(T14>300,"sim","não")) | AD14: =TRIM(IF(AND(ISNUMBER(R14),R14<=0),"t1 não é depois de t0; ","")&IF(AND(C14="C",ISNUMBER(R14),S14=""),"falta o tempo no painel; ","")&IF(AND(U14="sim",M14<>"F"),"acima do teto: deve ser F; ","")&IF(AND(V14="s",M14<>"F"),"encerrada: deve ser F; ","")&IF(AND(Y14="sim",M14<>"F"),"houve ajuda: deve ser F; ","")&IF(AND(M14<>"",ISNUMBER(R14)=FALSE()),"falta t0 ou t1; ","")) | AE14: =D14&"|"&C14 -> IHC-1|C
A15: 8 | B15: Sessão 1 · Bloco 1b | C15: C | D15: EDU-1 | E15: A | F15: EduComp 2026 — chamadas | G15: https://educomp.sbc.org.br/2026/ | H15: No site do EduComp 2026, descubra quem coordena a chamada de Minicursos. | I15: Maria Ivanilse Calderon Ribeiro (IFRO) | J15: S: o nome (ao menos prenome e um sobrenome; instituição opcional). P: abre a chamada certa, mas não lê o nome ou dá só o contato; ou responde os ministrantes listados em Programação > Minicursos. F: coordenação de outra chamada, desistência. | K15: 95 | P15: =IF(N15="","",IF(LEN(N15)-LEN(SUBSTITUTE(N15,":",""))=2,LEFT(N15,FIND(":",N15)-1)*3600+MID(N15,FIND(":",N15)+1,2)*60+RIGHT(N15,2),LEFT(N15,FIND(":",N15)-1)*60+RIGHT(N15,2))) | Q15: =IF(O15="","",IF(LEN(O15)-LEN(SUBSTITUTE(O15,":",""))=2,LEFT(O15,FIND(":",O15)-1)*3600+MID(O15,FIND(":",O15)+1,2)*60+RIGHT(O15,2),LEFT(O15,FIND(":",O15)-1)*60+RIGHT(O15,2))) | R15: =IF(OR(P15="",Q15=""),"",Q15-P15) | T15: =IF(R15="","",IF(AND(S15<>"",NOT(ISNUMBER(S15))),"painel inválido",R15-N(S15))) | U15: =IF(NOT(ISNUMBER(T15)),"",IF(T15>300,"sim","não")) | AD15: =TRIM(IF(AND(ISNUMBER(R15),R15<=0),"t1 não é depois de t0; ","")&IF(AND(C15="C",ISNUMBER(R15),S15=""),"falta o tempo no painel; ","")&IF(AND(U15="sim",M15<>"F"),"acima do teto: deve ser F; ","")&IF(AND(V15="s",M15<>"F"),"encerrada: deve ser F; ","")&IF(AND(Y15="sim",M15<>"F"),"houve ajuda: deve ser F; ","")&IF(AND(M15<>"",ISNUMBER(R15)=FALSE()),"falta t0 ou t1; ","")) | AE15: =D15&"|"&C15 -> EDU-1|C
A16: Pausa (10 min) · Bloco 2a — grupo G1, COM extensão (perfil C), variante B
A17: 9 | B17: Sessão 1 · Bloco 2a | C17: C | D17: SOL-1 | E17: B | F17: SOL — busca integrada | G17: https://sol.sbc.org.br/busca/ | H17: Na busca da biblioteca digital da SBC, a SOL, procure nos Anais de Eventos o artigo "Teaching or Manipulating? On the Adoption of Bright and Deceptive Patterns by Duolingo" e diga o nome do primeiro autor. | I17: João Vítor Castro (provavelmente "Castro, João Vítor"; confirmar no piloto) | J17: S: "João Vítor Castro", "João Castro" ou "Castro". P: chega ao resultado certo, mas diz o segundo autor (George Valença). F: não envia a busca, outro nome, desistência. | K17: 145 | P17: =IF(N17="","",IF(LEN(N17)-LEN(SUBSTITUTE(N17,":",""))=2,LEFT(N17,FIND(":",N17)-1)*3600+MID(N17,FIND(":",N17)+1,2)*60+RIGHT(N17,2),LEFT(N17,FIND(":",N17)-1)*60+RIGHT(N17,2))) | Q17: =IF(O17="","",IF(LEN(O17)-LEN(SUBSTITUTE(O17,":",""))=2,LEFT(O17,FIND(":",O17)-1)*3600+MID(O17,FIND(":",O17)+1,2)*60+RIGHT(O17,2),LEFT(O17,FIND(":",O17)-1)*60+RIGHT(O17,2))) | R17: =IF(OR(P17="",Q17=""),"",Q17-P17) | T17: =IF(R17="","",IF(AND(S17<>"",NOT(ISNUMBER(S17))),"painel inválido",R17-N(S17))) | U17: =IF(NOT(ISNUMBER(T17)),"",IF(T17>300,"sim","não")) | AD17: =TRIM(IF(AND(ISNUMBER(R17),R17<=0),"t1 não é depois de t0; ","")&IF(AND(C17="C",ISNUMBER(R17),S17=""),"falta o tempo no painel; ","")&IF(AND(U17="sim",M17<>"F"),"acima do teto: deve ser F; ","")&IF(AND(V17="s",M17<>"F"),"encerrada: deve ser F; ","")&IF(AND(Y17="sim",M17<>"F"),"houve ajuda: deve ser F; ","")&IF(AND(M17<>"",ISNUMBER(R17)=FALSE()),"falta t0 ou t1; ","")) | AE17: =D17&"|"&C17 -> SOL-1|C
A18: 10 | B18: Sessão 1 · Bloco 2a | C18: C | D18: CAPES-1 | E18: B | F18: Portal de Periódicos CAPES — Lista A–Z | G18: https://www.periodicos.capes.gov.br/index.php/acervo/lista-a-z-periodicos.html | H18: No Portal de Periódicos da CAPES, descubra qual é o ISSN do periódico Journal of the Brazilian Chemical Society. | I18: 0103-5053 | J18: S: 0103-5053 (hífen opcional). P: chegou à página do periódico sem ler o ISSN, ou deu um ISSN lido fora do Portal (SciELO). F: ISSN de outro título, desistência. | K18: 150 | P18: =IF(N18="","",IF(LEN(N18)-LEN(SUBSTITUTE(N18,":",""))=2,LEFT(N18,FIND(":",N18)-1)*3600+MID(N18,FIND(":",N18)+1,2)*60+RIGHT(N18,2),LEFT(N18,FIND(":",N18)-1)*60+RIGHT(N18,2))) | Q18: =IF(O18="","",IF(LEN(O18)-LEN(SUBSTITUTE(O18,":",""))=2,LEFT(O18,FIND(":",O18)-1)*3600+MID(O18,FIND(":",O18)+1,2)*60+RIGHT(O18,2),LEFT(O18,FIND(":",O18)-1)*60+RIGHT(O18,2))) | R18: =IF(OR(P18="",Q18=""),"",Q18-P18) | T18: =IF(R18="","",IF(AND(S18<>"",NOT(ISNUMBER(S18))),"painel inválido",R18-N(S18))) | U18: =IF(NOT(ISNUMBER(T18)),"",IF(T18>300,"sim","não")) | AD18: =TRIM(IF(AND(ISNUMBER(R18),R18<=0),"t1 não é depois de t0; ","")&IF(AND(C18="C",ISNUMBER(R18),S18=""),"falta o tempo no painel; ","")&IF(AND(U18="sim",M18<>"F"),"acima do teto: deve ser F; ","")&IF(AND(V18="s",M18<>"F"),"encerrada: deve ser F; ","")&IF(AND(Y18="sim",M18<>"F"),"houve ajuda: deve ser F; ","")&IF(AND(M18<>"",ISNUMBER(R18)=FALSE()),"falta t0 ou t1; ","")) | AE18: =D18&"|"&C18 -> CAPES-1|C
A19: 11 | B19: Sessão 1 · Bloco 2a | C19: C | D19: IHC-2 | E19: B | F19: IHC 2026 — Programação Geral | G19: https://ihc.sbc.org.br/2026/index.php/programacao/ | H19: Na página de programação do IHC 2026, sem baixar arquivos, descubra qual sessão técnica aconteceu na quarta-feira, 21 de outubro, às 10h30. | I19: Sessão Técnica 6 — Padrões Enganosos e Privacidade (Sala Juazeiro, 10h30–12h) | J19: S: número (6) ou tema (Padrões Enganosos e Privacidade). P: lê a linha certa, mas não diz qual é a sessão técnica. F: outro dia, outra linha, desistência. | K19: 90 | P19: =IF(N19="","",IF(LEN(N19)-LEN(SUBSTITUTE(N19,":",""))=2,LEFT(N19,FIND(":",N19)-1)*3600+MID(N19,FIND(":",N19)+1,2)*60+RIGHT(N19,2),LEFT(N19,FIND(":",N19)-1)*60+RIGHT(N19,2))) | Q19: =IF(O19="","",IF(LEN(O19)-LEN(SUBSTITUTE(O19,":",""))=2,LEFT(O19,FIND(":",O19)-1)*3600+MID(O19,FIND(":",O19)+1,2)*60+RIGHT(O19,2),LEFT(O19,FIND(":",O19)-1)*60+RIGHT(O19,2))) | R19: =IF(OR(P19="",Q19=""),"",Q19-P19) | T19: =IF(R19="","",IF(AND(S19<>"",NOT(ISNUMBER(S19))),"painel inválido",R19-N(S19))) | U19: =IF(NOT(ISNUMBER(T19)),"",IF(T19>300,"sim","não")) | AD19: =TRIM(IF(AND(ISNUMBER(R19),R19<=0),"t1 não é depois de t0; ","")&IF(AND(C19="C",ISNUMBER(R19),S19=""),"falta o tempo no painel; ","")&IF(AND(U19="sim",M19<>"F"),"acima do teto: deve ser F; ","")&IF(AND(V19="s",M19<>"F"),"encerrada: deve ser F; ","")&IF(AND(Y19="sim",M19<>"F"),"houve ajuda: deve ser F; ","")&IF(AND(M19<>"",ISNUMBER(R19)=FALSE()),"falta t0 ou t1; ","")) | AE19: =D19&"|"&C19 -> IHC-2|C
A20: 12 | B20: Sessão 1 · Bloco 2a | C20: C | D20: CSBC-2 | E20: B | F20: CSBC 2026 — rodapé de patrocinadores | G20: https://csbc.sbc.org.br/2026/ | H20: No site do CSBC 2026, o Congresso da SBC, descubra qual empresa é a patrocinadora da categoria Ouro. | I20: Qualcomm (aceitar o endereço qualcomm.com) | J20: S: "Qualcomm" ou o domínio. P: chega ao link da categoria Ouro, mas não consegue nomear a empresa. F: empresa de outra categoria, desistência. | K20: 120 | P20: =IF(N20="","",IF(LEN(N20)-LEN(SUBSTITUTE(N20,":",""))=2,LEFT(N20,FIND(":",N20)-1)*3600+MID(N20,FIND(":",N20)+1,2)*60+RIGHT(N20,2),LEFT(N20,FIND(":",N20)-1)*60+RIGHT(N20,2))) | Q20: =IF(O20="","",IF(LEN(O20)-LEN(SUBSTITUTE(O20,":",""))=2,LEFT(O20,FIND(":",O20)-1)*3600+MID(O20,FIND(":",O20)+1,2)*60+RIGHT(O20,2),LEFT(O20,FIND(":",O20)-1)*60+RIGHT(O20,2))) | R20: =IF(OR(P20="",Q20=""),"",Q20-P20) | T20: =IF(R20="","",IF(AND(S20<>"",NOT(ISNUMBER(S20))),"painel inválido",R20-N(S20))) | U20: =IF(NOT(ISNUMBER(T20)),"",IF(T20>300,"sim","não")) | AD20: =TRIM(IF(AND(ISNUMBER(R20),R20<=0),"t1 não é depois de t0; ","")&IF(AND(C20="C",ISNUMBER(R20),S20=""),"falta o tempo no painel; ","")&IF(AND(U20="sim",M20<>"F"),"acima do teto: deve ser F; ","")&IF(AND(V20="s",M20<>"F"),"encerrada: deve ser F; ","")&IF(AND(Y20="sim",M20<>"F"),"houve ajuda: deve ser F; ","")&IF(AND(M20<>"",ISNUMBER(R20)=FALSE()),"falta t0 ou t1; ","")) | AE20: =D20&"|"&C20 -> CSBC-2|C
A21: Trocar para o perfil S · Bloco 2b — grupo G2, SEM extensão, variante B · depois, entrevista final (10 min)
A22: 13 | B22: Sessão 1 · Bloco 2b | C22: S | D22: SOL-2 | E22: B | F22: SOL — anais do IHC 2025 | G22: https://sol.sbc.org.br/index.php/ihc/issue/view/1582 | H22: Nos anais do IHC 2025, na SOL, diga em qual trilha foi publicado o artigo "Diagnóstico da Acessibilidade Digital em Serviços Públicos Prioritários usando a Lei de Acesso à Informação". | I22: Ideias Inovadoras e Resultados Emergentes em IHC | J22: S: "Ideias Inovadoras e Resultados Emergentes em IHC" (aceitar "Ideias Inovadoras"). P: chega ao artigo, mas não identifica a trilha. F: outra trilha, desistência. | K22: 45 | P22: =IF(N22="","",IF(LEN(N22)-LEN(SUBSTITUTE(N22,":",""))=2,LEFT(N22,FIND(":",N22)-1)*3600+MID(N22,FIND(":",N22)+1,2)*60+RIGHT(N22,2),LEFT(N22,FIND(":",N22)-1)*60+RIGHT(N22,2))) | Q22: =IF(O22="","",IF(LEN(O22)-LEN(SUBSTITUTE(O22,":",""))=2,LEFT(O22,FIND(":",O22)-1)*3600+MID(O22,FIND(":",O22)+1,2)*60+RIGHT(O22,2),LEFT(O22,FIND(":",O22)-1)*60+RIGHT(O22,2))) | R22: =IF(OR(P22="",Q22=""),"",Q22-P22) | T22: =IF(R22="","",IF(AND(S22<>"",NOT(ISNUMBER(S22))),"painel inválido",R22-N(S22))) | U22: =IF(NOT(ISNUMBER(T22)),"",IF(T22>300,"sim","não")) | AD22: =TRIM(IF(AND(ISNUMBER(R22),R22<=0),"t1 não é depois de t0; ","")&IF(AND(C22="C",ISNUMBER(R22),S22=""),"falta o tempo no painel; ","")&IF(AND(U22="sim",M22<>"F"),"acima do teto: deve ser F; ","")&IF(AND(V22="s",M22<>"F"),"encerrada: deve ser F; ","")&IF(AND(Y22="sim",M22<>"F"),"houve ajuda: deve ser F; ","")&IF(AND(M22<>"",ISNUMBER(R22)=FALSE()),"falta t0 ou t1; ","")) | AE22: =D22&"|"&C22 -> SOL-2|S
A23: 14 | B23: Sessão 1 · Bloco 2b | C23: S | D23: CAPES-2 | E23: B | F23: Portal de Periódicos CAPES — Suporte regional | G23: https://www.periodicos.capes.gov.br/index.php/ajuda/suporte-regional.html | H23: No Portal de Periódicos da CAPES, encontre o e-mail de contato do suporte regional para a região Sudeste. | I23: cref@sibi.ufrj.br | J23: S: cref@sibi.ufrj.br. P: abre a região Sudeste, mas dá só o nome de uma bibliotecária, ou soletra o e-mail com 1 caractere errado. F: e-mail de outra região, desistência. | K23: 110 | P23: =IF(N23="","",IF(LEN(N23)-LEN(SUBSTITUTE(N23,":",""))=2,LEFT(N23,FIND(":",N23)-1)*3600+MID(N23,FIND(":",N23)+1,2)*60+RIGHT(N23,2),LEFT(N23,FIND(":",N23)-1)*60+RIGHT(N23,2))) | Q23: =IF(O23="","",IF(LEN(O23)-LEN(SUBSTITUTE(O23,":",""))=2,LEFT(O23,FIND(":",O23)-1)*3600+MID(O23,FIND(":",O23)+1,2)*60+RIGHT(O23,2),LEFT(O23,FIND(":",O23)-1)*60+RIGHT(O23,2))) | R23: =IF(OR(P23="",Q23=""),"",Q23-P23) | T23: =IF(R23="","",IF(AND(S23<>"",NOT(ISNUMBER(S23))),"painel inválido",R23-N(S23))) | U23: =IF(NOT(ISNUMBER(T23)),"",IF(T23>300,"sim","não")) | AD23: =TRIM(IF(AND(ISNUMBER(R23),R23<=0),"t1 não é depois de t0; ","")&IF(AND(C23="C",ISNUMBER(R23),S23=""),"falta o tempo no painel; ","")&IF(AND(U23="sim",M23<>"F"),"acima do teto: deve ser F; ","")&IF(AND(V23="s",M23<>"F"),"encerrada: deve ser F; ","")&IF(AND(Y23="sim",M23<>"F"),"houve ajuda: deve ser F; ","")&IF(AND(M23<>"",ISNUMBER(R23)=FALSE()),"falta t0 ou t1; ","")) | AE23: =D23&"|"&C23 -> CAPES-2|S
A24: 15 | B24: Sessão 1 · Bloco 2b | C24: S | D24: IHC-1 | E24: B | F24: IHC 2026 — Sessões Técnicas | G24: https://ihc.sbc.org.br/2026/ | H24: No site do IHC 2026, sem baixar arquivos, descubra em que dia, horário e sala foi apresentado o artigo "Lições Aprendidas sobre a Comunicabilidade da Ferramenta FAKECHECK: Uma Avaliação da Plataforma Web para Detecção de Notícias Falsas". | I24: Quarta-feira, 21/10, das 14h às 15h30, sala Juazeiro (Sessão Técnica 7) | J24: S: dia (quarta ou 21/10) + início 14h + sala Juazeiro. P: 2 dos 3 dados, ou só a sessão certa. F: dados de outra sessão, desistência. | K24: 105 | P24: =IF(N24="","",IF(LEN(N24)-LEN(SUBSTITUTE(N24,":",""))=2,LEFT(N24,FIND(":",N24)-1)*3600+MID(N24,FIND(":",N24)+1,2)*60+RIGHT(N24,2),LEFT(N24,FIND(":",N24)-1)*60+RIGHT(N24,2))) | Q24: =IF(O24="","",IF(LEN(O24)-LEN(SUBSTITUTE(O24,":",""))=2,LEFT(O24,FIND(":",O24)-1)*3600+MID(O24,FIND(":",O24)+1,2)*60+RIGHT(O24,2),LEFT(O24,FIND(":",O24)-1)*60+RIGHT(O24,2))) | R24: =IF(OR(P24="",Q24=""),"",Q24-P24) | T24: =IF(R24="","",IF(AND(S24<>"",NOT(ISNUMBER(S24))),"painel inválido",R24-N(S24))) | U24: =IF(NOT(ISNUMBER(T24)),"",IF(T24>300,"sim","não")) | AD24: =TRIM(IF(AND(ISNUMBER(R24),R24<=0),"t1 não é depois de t0; ","")&IF(AND(C24="C",ISNUMBER(R24),S24=""),"falta o tempo no painel; ","")&IF(AND(U24="sim",M24<>"F"),"acima do teto: deve ser F; ","")&IF(AND(V24="s",M24<>"F"),"encerrada: deve ser F; ","")&IF(AND(Y24="sim",M24<>"F"),"houve ajuda: deve ser F; ","")&IF(AND(M24<>"",ISNUMBER(R24)=FALSE()),"falta t0 ou t1; ","")) | AE24: =D24&"|"&C24 -> IHC-1|S
A25: 16 | B25: Sessão 1 · Bloco 2b | C25: S | D25: EDU-1 | E25: B | F25: EduComp 2026 — chamadas | G25: https://educomp.sbc.org.br/2026/ | H25: No site do EduComp 2026, descubra quem coordena a chamada de Mesas temáticas. | I25: Jefferson Rodrigo Speck (Faculdade Donaduzzi/Unioeste) | J25: S: o nome (ao menos prenome e um sobrenome). P: abre a chamada certa, mas não lê o nome ou dá só o contato; ou responde os mediadores de uma mesa (Programação > Mesas temáticas). F: coordenação de outra chamada, desistência. | K25: 55 | P25: =IF(N25="","",IF(LEN(N25)-LEN(SUBSTITUTE(N25,":",""))=2,LEFT(N25,FIND(":",N25)-1)*3600+MID(N25,FIND(":",N25)+1,2)*60+RIGHT(N25,2),LEFT(N25,FIND(":",N25)-1)*60+RIGHT(N25,2))) | Q25: =IF(O25="","",IF(LEN(O25)-LEN(SUBSTITUTE(O25,":",""))=2,LEFT(O25,FIND(":",O25)-1)*3600+MID(O25,FIND(":",O25)+1,2)*60+RIGHT(O25,2),LEFT(O25,FIND(":",O25)-1)*60+RIGHT(O25,2))) | R25: =IF(OR(P25="",Q25=""),"",Q25-P25) | T25: =IF(R25="","",IF(AND(S25<>"",NOT(ISNUMBER(S25))),"painel inválido",R25-N(S25))) | U25: =IF(NOT(ISNUMBER(T25)),"",IF(T25>300,"sim","não")) | AD25: =TRIM(IF(AND(ISNUMBER(R25),R25<=0),"t1 não é depois de t0; ","")&IF(AND(C25="C",ISNUMBER(R25),S25=""),"falta o tempo no painel; ","")&IF(AND(U25="sim",M25<>"F"),"acima do teto: deve ser F; ","")&IF(AND(V25="s",M25<>"F"),"encerrada: deve ser F; ","")&IF(AND(Y25="sim",M25<>"F"),"houve ajuda: deve ser F; ","")&IF(AND(M25<>"",ISNUMBER(R25)=FALSE()),"falta t0 ou t1; ","")) | AE25: =D25&"|"&C25 -> EDU-1|S
A26: Sessão 2 (complementar) · Preparação (10 min) · Bloco 3a — grupo G1, SEM extensão (perfil S), variante A
A27: 17 | B27: Sessão 2 · Bloco 3a | C27: S | D27: JIS-1 | E27: A | F27: JIS — volume 16 (2025) | G27: https://journals-sol.sbc.org.br/index.php/jis | H27: No Journal on Interactive Systems, descubra em quais páginas do volume de 2025 está publicado o artigo "Kahoot as a data collection tool to work with school age children". | I27: 227–235 | J27: S: 227 a 235. P: chega ao artigo, mas dá as páginas de um vizinho. F: não chega ao volume de 2025, desistência. | K27: 70 | P27: =IF(N27="","",IF(LEN(N27)-LEN(SUBSTITUTE(N27,":",""))=2,LEFT(N27,FIND(":",N27)-1)*3600+MID(N27,FIND(":",N27)+1,2)*60+RIGHT(N27,2),LEFT(N27,FIND(":",N27)-1)*60+RIGHT(N27,2))) | Q27: =IF(O27="","",IF(LEN(O27)-LEN(SUBSTITUTE(O27,":",""))=2,LEFT(O27,FIND(":",O27)-1)*3600+MID(O27,FIND(":",O27)+1,2)*60+RIGHT(O27,2),LEFT(O27,FIND(":",O27)-1)*60+RIGHT(O27,2))) | R27: =IF(OR(P27="",Q27=""),"",Q27-P27) | T27: =IF(R27="","",IF(AND(S27<>"",NOT(ISNUMBER(S27))),"painel inválido",R27-N(S27))) | U27: =IF(NOT(ISNUMBER(T27)),"",IF(T27>300,"sim","não")) | AD27: =TRIM(IF(AND(ISNUMBER(R27),R27<=0),"t1 não é depois de t0; ","")&IF(AND(C27="C",ISNUMBER(R27),S27=""),"falta o tempo no painel; ","")&IF(AND(U27="sim",M27<>"F"),"acima do teto: deve ser F; ","")&IF(AND(V27="s",M27<>"F"),"encerrada: deve ser F; ","")&IF(AND(Y27="sim",M27<>"F"),"houve ajuda: deve ser F; ","")&IF(AND(M27<>"",ISNUMBER(R27)=FALSE()),"falta t0 ou t1; ","")) | AE27: =D27&"|"&C27 -> JIS-1|S
A28: 18 | B28: Sessão 2 · Bloco 3a | C28: S | D28: EDU-3 | E28: A | F28: EduComp 2026 — Comitê de programa | G28: https://educomp.sbc.org.br/2026/educomp/equipes/comite-programa.html | H28: No comitê de programa do EduComp 2026, descubra de quais instituições são os coordenadores da Trilha 2, Relatos de experiência. | I28: UEA e UFRR (Fernanda Pires — UEA; Luciano Ferreira — UFRR) | J28: S: as duas instituições. P: só uma, ou os nomes sem as instituições. F: instituições de outra trilha, desistência. | K28: 35 | P28: =IF(N28="","",IF(LEN(N28)-LEN(SUBSTITUTE(N28,":",""))=2,LEFT(N28,FIND(":",N28)-1)*3600+MID(N28,FIND(":",N28)+1,2)*60+RIGHT(N28,2),LEFT(N28,FIND(":",N28)-1)*60+RIGHT(N28,2))) | Q28: =IF(O28="","",IF(LEN(O28)-LEN(SUBSTITUTE(O28,":",""))=2,LEFT(O28,FIND(":",O28)-1)*3600+MID(O28,FIND(":",O28)+1,2)*60+RIGHT(O28,2),LEFT(O28,FIND(":",O28)-1)*60+RIGHT(O28,2))) | R28: =IF(OR(P28="",Q28=""),"",Q28-P28) | T28: =IF(R28="","",IF(AND(S28<>"",NOT(ISNUMBER(S28))),"painel inválido",R28-N(S28))) | U28: =IF(NOT(ISNUMBER(T28)),"",IF(T28>300,"sim","não")) | AD28: =TRIM(IF(AND(ISNUMBER(R28),R28<=0),"t1 não é depois de t0; ","")&IF(AND(C28="C",ISNUMBER(R28),S28=""),"falta o tempo no painel; ","")&IF(AND(U28="sim",M28<>"F"),"acima do teto: deve ser F; ","")&IF(AND(V28="s",M28<>"F"),"encerrada: deve ser F; ","")&IF(AND(Y28="sim",M28<>"F"),"houve ajuda: deve ser F; ","")&IF(AND(M28<>"",ISNUMBER(R28)=FALSE()),"falta t0 ou t1; ","")) | AE28: =D28&"|"&C28 -> EDU-3|S
A29: Trocar para o perfil C · Bloco 3b — grupo G2, COM extensão, variante A
A30: 19 | B30: Sessão 2 · Bloco 3b | C30: C | D30: SBC-1 | E30: A | F30: SBC — Associe-se | G30: https://www.sbc.org.br/ | H30: No site da SBC, descubra qual é o valor atual da anuidade para a categoria Associado ou Associada Estudante de Pós-graduação. | I30: R$ 142,00 | J30: S: R$ 142,00. P: chega à tabela de anuidades, mas lê o valor de outra linha. F: valor desatualizado da notícia de 2017 (R$ 70, 75, 175 ou 195), não chega à tabela, desistência. | K30: 130 | P30: =IF(N30="","",IF(LEN(N30)-LEN(SUBSTITUTE(N30,":",""))=2,LEFT(N30,FIND(":",N30)-1)*3600+MID(N30,FIND(":",N30)+1,2)*60+RIGHT(N30,2),LEFT(N30,FIND(":",N30)-1)*60+RIGHT(N30,2))) | Q30: =IF(O30="","",IF(LEN(O30)-LEN(SUBSTITUTE(O30,":",""))=2,LEFT(O30,FIND(":",O30)-1)*3600+MID(O30,FIND(":",O30)+1,2)*60+RIGHT(O30,2),LEFT(O30,FIND(":",O30)-1)*60+RIGHT(O30,2))) | R30: =IF(OR(P30="",Q30=""),"",Q30-P30) | T30: =IF(R30="","",IF(AND(S30<>"",NOT(ISNUMBER(S30))),"painel inválido",R30-N(S30))) | U30: =IF(NOT(ISNUMBER(T30)),"",IF(T30>300,"sim","não")) | AD30: =TRIM(IF(AND(ISNUMBER(R30),R30<=0),"t1 não é depois de t0; ","")&IF(AND(C30="C",ISNUMBER(R30),S30=""),"falta o tempo no painel; ","")&IF(AND(U30="sim",M30<>"F"),"acima do teto: deve ser F; ","")&IF(AND(V30="s",M30<>"F"),"encerrada: deve ser F; ","")&IF(AND(Y30="sim",M30<>"F"),"houve ajuda: deve ser F; ","")&IF(AND(M30<>"",ISNUMBER(R30)=FALSE()),"falta t0 ou t1; ","")) | AE30: =D30&"|"&C30 -> SBC-1|C
A31: 20 | B31: Sessão 2 · Bloco 3b | C31: C | D31: SBC-2 | E31: A | F31: SBC — Secretarias Regionais | G31: https://www.sbc.org.br/ | H31: No site da SBC, descubra quem é o secretário ou a secretária regional da SBC em Pernambuco. | I31: Kiev Gama | J31: S: "Kiev Gama". P: lê outra coluna da linha certa, ou dá a secretária adjunta (Taciana Pontual Falcão, na página do estado). F: nome de outro estado, não chega à tabela, desistência. | K31: 105 | P31: =IF(N31="","",IF(LEN(N31)-LEN(SUBSTITUTE(N31,":",""))=2,LEFT(N31,FIND(":",N31)-1)*3600+MID(N31,FIND(":",N31)+1,2)*60+RIGHT(N31,2),LEFT(N31,FIND(":",N31)-1)*60+RIGHT(N31,2))) | Q31: =IF(O31="","",IF(LEN(O31)-LEN(SUBSTITUTE(O31,":",""))=2,LEFT(O31,FIND(":",O31)-1)*3600+MID(O31,FIND(":",O31)+1,2)*60+RIGHT(O31,2),LEFT(O31,FIND(":",O31)-1)*60+RIGHT(O31,2))) | R31: =IF(OR(P31="",Q31=""),"",Q31-P31) | T31: =IF(R31="","",IF(AND(S31<>"",NOT(ISNUMBER(S31))),"painel inválido",R31-N(S31))) | U31: =IF(NOT(ISNUMBER(T31)),"",IF(T31>300,"sim","não")) | AD31: =TRIM(IF(AND(ISNUMBER(R31),R31<=0),"t1 não é depois de t0; ","")&IF(AND(C31="C",ISNUMBER(R31),S31=""),"falta o tempo no painel; ","")&IF(AND(U31="sim",M31<>"F"),"acima do teto: deve ser F; ","")&IF(AND(V31="s",M31<>"F"),"encerrada: deve ser F; ","")&IF(AND(Y31="sim",M31<>"F"),"houve ajuda: deve ser F; ","")&IF(AND(M31<>"",ISNUMBER(R31)=FALSE()),"falta t0 ou t1; ","")) | AE31: =D31&"|"&C31 -> SBC-2|C
A32: Bloco 4a — grupo G1, COM extensão (perfil C), variante B
A33: 21 | B33: Sessão 2 · Bloco 4a | C33: C | D33: JIS-1 | E33: B | F33: JIS — volume 16 (2025) | G33: https://journals-sol.sbc.org.br/index.php/jis | H33: No Journal on Interactive Systems, descubra em quais páginas do volume de 2025 está publicado o artigo "Evaluating a Serious Game for Math: Is it Useful and Fun?". | I33: 199–212 | J33: S: 199 a 212. P: chega ao artigo, mas dá as páginas de um vizinho. F: não chega ao volume de 2025, desistência. | K33: 130 | P33: =IF(N33="","",IF(LEN(N33)-LEN(SUBSTITUTE(N33,":",""))=2,LEFT(N33,FIND(":",N33)-1)*3600+MID(N33,FIND(":",N33)+1,2)*60+RIGHT(N33,2),LEFT(N33,FIND(":",N33)-1)*60+RIGHT(N33,2))) | Q33: =IF(O33="","",IF(LEN(O33)-LEN(SUBSTITUTE(O33,":",""))=2,LEFT(O33,FIND(":",O33)-1)*3600+MID(O33,FIND(":",O33)+1,2)*60+RIGHT(O33,2),LEFT(O33,FIND(":",O33)-1)*60+RIGHT(O33,2))) | R33: =IF(OR(P33="",Q33=""),"",Q33-P33) | T33: =IF(R33="","",IF(AND(S33<>"",NOT(ISNUMBER(S33))),"painel inválido",R33-N(S33))) | U33: =IF(NOT(ISNUMBER(T33)),"",IF(T33>300,"sim","não")) | AD33: =TRIM(IF(AND(ISNUMBER(R33),R33<=0),"t1 não é depois de t0; ","")&IF(AND(C33="C",ISNUMBER(R33),S33=""),"falta o tempo no painel; ","")&IF(AND(U33="sim",M33<>"F"),"acima do teto: deve ser F; ","")&IF(AND(V33="s",M33<>"F"),"encerrada: deve ser F; ","")&IF(AND(Y33="sim",M33<>"F"),"houve ajuda: deve ser F; ","")&IF(AND(M33<>"",ISNUMBER(R33)=FALSE()),"falta t0 ou t1; ","")) | AE33: =D33&"|"&C33 -> JIS-1|C
A34: 22 | B34: Sessão 2 · Bloco 4a | C34: C | D34: EDU-3 | E34: B | F34: EduComp 2026 — Comitê de programa | G34: https://educomp.sbc.org.br/2026/educomp/equipes/comite-programa.html | H34: No comitê de programa do EduComp 2026, descubra de quais instituições são os coordenadores da Trilha 4, Recursos e ambientes educacionais. | I34: UFMG e UFJF (Eduardo Figueiredo — UFMG; Ronney Castro — UFJF) | J34: S: as duas instituições. P: só uma, ou os nomes sem as instituições. F: instituições de outra trilha, desistência. | K34: 55 | P34: =IF(N34="","",IF(LEN(N34)-LEN(SUBSTITUTE(N34,":",""))=2,LEFT(N34,FIND(":",N34)-1)*3600+MID(N34,FIND(":",N34)+1,2)*60+RIGHT(N34,2),LEFT(N34,FIND(":",N34)-1)*60+RIGHT(N34,2))) | Q34: =IF(O34="","",IF(LEN(O34)-LEN(SUBSTITUTE(O34,":",""))=2,LEFT(O34,FIND(":",O34)-1)*3600+MID(O34,FIND(":",O34)+1,2)*60+RIGHT(O34,2),LEFT(O34,FIND(":",O34)-1)*60+RIGHT(O34,2))) | R34: =IF(OR(P34="",Q34=""),"",Q34-P34) | T34: =IF(R34="","",IF(AND(S34<>"",NOT(ISNUMBER(S34))),"painel inválido",R34-N(S34))) | U34: =IF(NOT(ISNUMBER(T34)),"",IF(T34>300,"sim","não")) | AD34: =TRIM(IF(AND(ISNUMBER(R34),R34<=0),"t1 não é depois de t0; ","")&IF(AND(C34="C",ISNUMBER(R34),S34=""),"falta o tempo no painel; ","")&IF(AND(U34="sim",M34<>"F"),"acima do teto: deve ser F; ","")&IF(AND(V34="s",M34<>"F"),"encerrada: deve ser F; ","")&IF(AND(Y34="sim",M34<>"F"),"houve ajuda: deve ser F; ","")&IF(AND(M34<>"",ISNUMBER(R34)=FALSE()),"falta t0 ou t1; ","")) | AE34: =D34&"|"&C34 -> EDU-3|C
A35: Trocar para o perfil S · Bloco 4b — grupo G2, SEM extensão, variante B · entrevista curta (5 min)
A36: 23 | B36: Sessão 2 · Bloco 4b | C36: S | D36: SBC-1 | E36: B | F36: SBC — Associe-se | G36: https://www.sbc.org.br/ | H36: No site da SBC, descubra qual é o valor atual da anuidade para a categoria Associado ou Associada Efetivo/Fundador. | I36: R$ 394,00 | J36: S: R$ 394,00. P: chega à tabela, mas lê o valor de outra linha. F: valor desatualizado da notícia de 2017 (R$ 70, 75, 175 ou 195), não chega à tabela, desistência. | K36: 90 | P36: =IF(N36="","",IF(LEN(N36)-LEN(SUBSTITUTE(N36,":",""))=2,LEFT(N36,FIND(":",N36)-1)*3600+MID(N36,FIND(":",N36)+1,2)*60+RIGHT(N36,2),LEFT(N36,FIND(":",N36)-1)*60+RIGHT(N36,2))) | Q36: =IF(O36="","",IF(LEN(O36)-LEN(SUBSTITUTE(O36,":",""))=2,LEFT(O36,FIND(":",O36)-1)*3600+MID(O36,FIND(":",O36)+1,2)*60+RIGHT(O36,2),LEFT(O36,FIND(":",O36)-1)*60+RIGHT(O36,2))) | R36: =IF(OR(P36="",Q36=""),"",Q36-P36) | T36: =IF(R36="","",IF(AND(S36<>"",NOT(ISNUMBER(S36))),"painel inválido",R36-N(S36))) | U36: =IF(NOT(ISNUMBER(T36)),"",IF(T36>300,"sim","não")) | AD36: =TRIM(IF(AND(ISNUMBER(R36),R36<=0),"t1 não é depois de t0; ","")&IF(AND(C36="C",ISNUMBER(R36),S36=""),"falta o tempo no painel; ","")&IF(AND(U36="sim",M36<>"F"),"acima do teto: deve ser F; ","")&IF(AND(V36="s",M36<>"F"),"encerrada: deve ser F; ","")&IF(AND(Y36="sim",M36<>"F"),"houve ajuda: deve ser F; ","")&IF(AND(M36<>"",ISNUMBER(R36)=FALSE()),"falta t0 ou t1; ","")) | AE36: =D36&"|"&C36 -> SBC-1|S
A37: 24 | B37: Sessão 2 · Bloco 4b | C37: S | D37: SBC-2 | E37: B | F37: SBC — Secretarias Regionais | G37: https://www.sbc.org.br/ | H37: No site da SBC, descubra quem é o secretário ou a secretária regional da SBC em Roraima. | I37: Herbert Rocha | J37: S: "Herbert Rocha". P: lê outra coluna da linha certa. F: nome de outro estado, não chega à tabela, desistência. | K37: 65 | P37: =IF(N37="","",IF(LEN(N37)-LEN(SUBSTITUTE(N37,":",""))=2,LEFT(N37,FIND(":",N37)-1)*3600+MID(N37,FIND(":",N37)+1,2)*60+RIGHT(N37,2),LEFT(N37,FIND(":",N37)-1)*60+RIGHT(N37,2))) | Q37: =IF(O37="","",IF(LEN(O37)-LEN(SUBSTITUTE(O37,":",""))=2,LEFT(O37,FIND(":",O37)-1)*3600+MID(O37,FIND(":",O37)+1,2)*60+RIGHT(O37,2),LEFT(O37,FIND(":",O37)-1)*60+RIGHT(O37,2))) | R37: =IF(OR(P37="",Q37=""),"",Q37-P37) | T37: =IF(R37="","",IF(AND(S37<>"",NOT(ISNUMBER(S37))),"painel inválido",R37-N(S37))) | U37: =IF(NOT(ISNUMBER(T37)),"",IF(T37>300,"sim","não")) | AD37: =TRIM(IF(AND(ISNUMBER(R37),R37<=0),"t1 não é depois de t0; ","")&IF(AND(C37="C",ISNUMBER(R37),S37=""),"falta o tempo no painel; ","")&IF(AND(U37="sim",M37<>"F"),"acima do teto: deve ser F; ","")&IF(AND(V37="s",M37<>"F"),"encerrada: deve ser F; ","")&IF(AND(Y37="sim",M37<>"F"),"houve ajuda: deve ser F; ","")&IF(AND(M37<>"",ISNUMBER(R37)=FALSE()),"falta t0 ou t1; ","")) | AE37: =D37&"|"&C37 -> SBC-2|S

Sheet Resumo
A1: Resumo (calculado a partir do Roteiro)
A2: Uma avaliadora: relatar os valores por tarefa e as contagens; médias são só descritivas. Só entram linhas com resultado S, P ou F. Tempos em segundos.
A4: Condição | B4: Execuções com resultado | C4: Sucesso (S) | D4: Parcial (P) | E4: Falha (F) | F4: Taxa de sucesso | G4: Tempo total médio | H4: Tempo líquido médio | I4: SEQ médio | J4: Acima do teto
A5: S | B5: =COUNTIFS(Roteiro!$C$5:$C$37,$A5,Roteiro!$M$5:$M$37,"S")+COUNTIFS(Roteiro!$C$5:$C$37,$A5,Roteiro!$M$5:$M$37,"P")+COUNTIFS(Roteiro!$C$5:$C$37,$A5,Roteiro!$M$5:$M$37,"F") -> 0 | C5: =COUNTIFS(Roteiro!$C$5:$C$37,$A5,Roteiro!$M$5:$M$37,"S") -> 0 | D5: =COUNTIFS(Roteiro!$C$5:$C$37,$A5,Roteiro!$M$5:$M$37,"P") -> 0 | E5: =COUNTIFS(Roteiro!$C$5:$C$37,$A5,Roteiro!$M$5:$M$37,"F") -> 0 | F5: =IF(B5=0,"",C5/B5) | G5: =IFERROR((SUMIFS(Roteiro!$R$5:$R$37,Roteiro!$C$5:$C$37,$A5,Roteiro!$M$5:$M$37,"S")+SUMIFS(Roteiro!$R$5:$R$37,Roteiro!$C$5:$C$37,$A5,Roteiro!$M$5:$M$37,"P")+SUMIFS(Roteiro!$R$5:$R$37,Roteiro!$C$5:$C$37,$A5,Roteiro!$M$5:$M$37,"F"))/(COUNTIFS(Roteiro!$C$5:$C$37,$A5,Roteiro!$M$5:$M$37,"S",Roteiro!$R$5:$R$37,">-1E+300")+COUNTIFS(Roteiro!$C$5:$C$37,$A5,Roteiro!$M$5:$M$37,"P",Roteiro!$R$5:$R$37,">-1E+300")+COUNTIFS(Roteiro!$C$5:$C$37,$A5,Roteiro!$M$5:$M$37,"F",Roteiro!$R$5:$R$37,">-1E+300")),"") | H5: =IFERROR((SUMIFS(Roteiro!$T$5:$T$37,Roteiro!$C$5:$C$37,$A5,Roteiro!$M$5:$M$37,"S")+SUMIFS(Roteiro!$T$5:$T$37,Roteiro!$C$5:$C$37,$A5,Roteiro!$M$5:$M$37,"P")+SUMIFS(Roteiro!$T$5:$T$37,Roteiro!$C$5:$C$37,$A5,Roteiro!$M$5:$M$37,"F"))/(COUNTIFS(Roteiro!$C$5:$C$37,$A5,Roteiro!$M$5:$M$37,"S",Roteiro!$T$5:$T$37,">-1E+300")+COUNTIFS(Roteiro!$C$5:$C$37,$A5,Roteiro!$M$5:$M$37,"P",Roteiro!$T$5:$T$37,">-1E+300")+COUNTIFS(Roteiro!$C$5:$C$37,$A5,Roteiro!$M$5:$M$37,"F",Roteiro!$T$5:$T$37,">-1E+300")),"") | I5: =IFERROR((SUMIFS(Roteiro!$Z$5:$Z$37,Roteiro!$C$5:$C$37,$A5,Roteiro!$M$5:$M$37,"S")+SUMIFS(Roteiro!$Z$5:$Z$37,Roteiro!$C$5:$C$37,$A5,Roteiro!$M$5:$M$37,"P")+SUMIFS(Roteiro!$Z$5:$Z$37,Roteiro!$C$5:$C$37,$A5,Roteiro!$M$5:$M$37,"F"))/(COUNTIFS(Roteiro!$C$5:$C$37,$A5,Roteiro!$M$5:$M$37,"S",Roteiro!$Z$5:$Z$37,">-1E+300")+COUNTIFS(Roteiro!$C$5:$C$37,$A5,Roteiro!$M$5:$M$37,"P",Roteiro!$Z$5:$Z$37,">-1E+300")+COUNTIFS(Roteiro!$C$5:$C$37,$A5,Roteiro!$M$5:$M$37,"F",Roteiro!$Z$5:$Z$37,">-1E+300")),"") | J5: =COUNTIFS(Roteiro!$C$5:$C$37,$A5,Roteiro!$U$5:$U$37,"sim") -> 0
A6: C | B6: =COUNTIFS(Roteiro!$C$5:$C$37,$A6,Roteiro!$M$5:$M$37,"S")+COUNTIFS(Roteiro!$C$5:$C$37,$A6,Roteiro!$M$5:$M$37,"P")+COUNTIFS(Roteiro!$C$5:$C$37,$A6,Roteiro!$M$5:$M$37,"F") -> 0 | C6: =COUNTIFS(Roteiro!$C$5:$C$37,$A6,Roteiro!$M$5:$M$37,"S") -> 0 | D6: =COUNTIFS(Roteiro!$C$5:$C$37,$A6,Roteiro!$M$5:$M$37,"P") -> 0 | E6: =COUNTIFS(Roteiro!$C$5:$C$37,$A6,Roteiro!$M$5:$M$37,"F") -> 0 | F6: =IF(B6=0,"",C6/B6) | G6: =IFERROR((SUMIFS(Roteiro!$R$5:$R$37,Roteiro!$C$5:$C$37,$A6,Roteiro!$M$5:$M$37,"S")+SUMIFS(Roteiro!$R$5:$R$37,Roteiro!$C$5:$C$37,$A6,Roteiro!$M$5:$M$37,"P")+SUMIFS(Roteiro!$R$5:$R$37,Roteiro!$C$5:$C$37,$A6,Roteiro!$M$5:$M$37,"F"))/(COUNTIFS(Roteiro!$C$5:$C$37,$A6,Roteiro!$M$5:$M$37,"S",Roteiro!$R$5:$R$37,">-1E+300")+COUNTIFS(Roteiro!$C$5:$C$37,$A6,Roteiro!$M$5:$M$37,"P",Roteiro!$R$5:$R$37,">-1E+300")+COUNTIFS(Roteiro!$C$5:$C$37,$A6,Roteiro!$M$5:$M$37,"F",Roteiro!$R$5:$R$37,">-1E+300")),"") | H6: =IFERROR((SUMIFS(Roteiro!$T$5:$T$37,Roteiro!$C$5:$C$37,$A6,Roteiro!$M$5:$M$37,"S")+SUMIFS(Roteiro!$T$5:$T$37,Roteiro!$C$5:$C$37,$A6,Roteiro!$M$5:$M$37,"P")+SUMIFS(Roteiro!$T$5:$T$37,Roteiro!$C$5:$C$37,$A6,Roteiro!$M$5:$M$37,"F"))/(COUNTIFS(Roteiro!$C$5:$C$37,$A6,Roteiro!$M$5:$M$37,"S",Roteiro!$T$5:$T$37,">-1E+300")+COUNTIFS(Roteiro!$C$5:$C$37,$A6,Roteiro!$M$5:$M$37,"P",Roteiro!$T$5:$T$37,">-1E+300")+COUNTIFS(Roteiro!$C$5:$C$37,$A6,Roteiro!$M$5:$M$37,"F",Roteiro!$T$5:$T$37,">-1E+300")),"") | I6: =IFERROR((SUMIFS(Roteiro!$Z$5:$Z$37,Roteiro!$C$5:$C$37,$A6,Roteiro!$M$5:$M$37,"S")+SUMIFS(Roteiro!$Z$5:$Z$37,Roteiro!$C$5:$C$37,$A6,Roteiro!$M$5:$M$37,"P")+SUMIFS(Roteiro!$Z$5:$Z$37,Roteiro!$C$5:$C$37,$A6,Roteiro!$M$5:$M$37,"F"))/(COUNTIFS(Roteiro!$C$5:$C$37,$A6,Roteiro!$M$5:$M$37,"S",Roteiro!$Z$5:$Z$37,">-1E+300")+COUNTIFS(Roteiro!$C$5:$C$37,$A6,Roteiro!$M$5:$M$37,"P",Roteiro!$Z$5:$Z$37,">-1E+300")+COUNTIFS(Roteiro!$C$5:$C$37,$A6,Roteiro!$M$5:$M$37,"F",Roteiro!$Z$5:$Z$37,">-1E+300")),"") | J6: =COUNTIFS(Roteiro!$C$5:$C$37,$A6,Roteiro!$U$5:$U$37,"sim") -> 0
A9: Por tarefa (variantes A e B nas duas condições; a tarefa vem do Roteiro, então uma troca feita lá aparece aqui)
A10: Tarefa | B10: Conjunto | C10: Grupo | D10: Efeito previsto | E10: Resultado S | F10: Resultado C | G10: Tempo total S | H10: Tempo total C | I10: Diferença C − S | J10: Tempo líquido S | K10: Tempo líquido C | L10: Diferença líquida C − S | M10: SEQ S | N10: SEQ C
A11: =Roteiro!D6 -> SOL-1 | B11: =IFERROR(INDEX(Tarefas!$B$2:$B$20,MATCH($A11,Tarefas!$A$2:$A$20,0)),"") -> Núcleo | C11: =IFERROR(INDEX(Tarefas!$C$2:$C$20,MATCH($A11,Tarefas!$A$2:$A$20,0)),"") -> G1 | D11: =IFERROR(INDEX(Tarefas!$G$2:$G$20,MATCH($A11,Tarefas!$A$2:$A$20,0)),"") -> baixo | E11: =IFERROR(IF(INDEX(Roteiro!$M$5:$M$37,MATCH($A11&"|S",Roteiro!$AE$5:$AE$37,0))="","",INDEX(Roteiro!$M$5:$M$37,MATCH($A11&"|S",Roteiro!$AE$5:$AE$37,0))),"") | F11: =IFERROR(IF(INDEX(Roteiro!$M$5:$M$37,MATCH($A11&"|C",Roteiro!$AE$5:$AE$37,0))="","",INDEX(Roteiro!$M$5:$M$37,MATCH($A11&"|C",Roteiro!$AE$5:$AE$37,0))),"") | G11: =IFERROR(IF(INDEX(Roteiro!$R$5:$R$37,MATCH($A11&"|S",Roteiro!$AE$5:$AE$37,0))="","",INDEX(Roteiro!$R$5:$R$37,MATCH($A11&"|S",Roteiro!$AE$5:$AE$37,0))),"") | H11: =IFERROR(IF(INDEX(Roteiro!$R$5:$R$37,MATCH($A11&"|C",Roteiro!$AE$5:$AE$37,0))="","",INDEX(Roteiro!$R$5:$R$37,MATCH($A11&"|C",Roteiro!$AE$5:$AE$37,0))),"") | I11: =IF(AND(ISNUMBER(G11),ISNUMBER(H11)),H11-G11,"") | J11: =IFERROR(IF(INDEX(Roteiro!$T$5:$T$37,MATCH($A11&"|S",Roteiro!$AE$5:$AE$37,0))="","",INDEX(Roteiro!$T$5:$T$37,MATCH($A11&"|S",Roteiro!$AE$5:$AE$37,0))),"") | K11: =IFERROR(IF(INDEX(Roteiro!$T$5:$T$37,MATCH($A11&"|C",Roteiro!$AE$5:$AE$37,0))="","",INDEX(Roteiro!$T$5:$T$37,MATCH($A11&"|C",Roteiro!$AE$5:$AE$37,0))),"") | L11: =IF(AND(ISNUMBER(J11),ISNUMBER(K11)),K11-J11,"") | M11: =IFERROR(IF(INDEX(Roteiro!$Z$5:$Z$37,MATCH($A11&"|S",Roteiro!$AE$5:$AE$37,0))="","",INDEX(Roteiro!$Z$5:$Z$37,MATCH($A11&"|S",Roteiro!$AE$5:$AE$37,0))),"") | N11: =IFERROR(IF(INDEX(Roteiro!$Z$5:$Z$37,MATCH($A11&"|C",Roteiro!$AE$5:$AE$37,0))="","",INDEX(Roteiro!$Z$5:$Z$37,MATCH($A11&"|C",Roteiro!$AE$5:$AE$37,0))),"")
A12: =Roteiro!D7 -> CAPES-1 | B12: =IFERROR(INDEX(Tarefas!$B$2:$B$20,MATCH($A12,Tarefas!$A$2:$A$20,0)),"") -> Núcleo | C12: =IFERROR(INDEX(Tarefas!$C$2:$C$20,MATCH($A12,Tarefas!$A$2:$A$20,0)),"") -> G1 | D12: =IFERROR(INDEX(Tarefas!$G$2:$G$20,MATCH($A12,Tarefas!$A$2:$A$20,0)),"") -> baixo | E12: =IFERROR(IF(INDEX(Roteiro!$M$5:$M$37,MATCH($A12&"|S",Roteiro!$AE$5:$AE$37,0))="","",INDEX(Roteiro!$M$5:$M$37,MATCH($A12&"|S",Roteiro!$AE$5:$AE$37,0))),"") | F12: =IFERROR(IF(INDEX(Roteiro!$M$5:$M$37,MATCH($A12&"|C",Roteiro!$AE$5:$AE$37,0))="","",INDEX(Roteiro!$M$5:$M$37,MATCH($A12&"|C",Roteiro!$AE$5:$AE$37,0))),"") | G12: =IFERROR(IF(INDEX(Roteiro!$R$5:$R$37,MATCH($A12&"|S",Roteiro!$AE$5:$AE$37,0))="","",INDEX(Roteiro!$R$5:$R$37,MATCH($A12&"|S",Roteiro!$AE$5:$AE$37,0))),"") | H12: =IFERROR(IF(INDEX(Roteiro!$R$5:$R$37,MATCH($A12&"|C",Roteiro!$AE$5:$AE$37,0))="","",INDEX(Roteiro!$R$5:$R$37,MATCH($A12&"|C",Roteiro!$AE$5:$AE$37,0))),"") | I12: =IF(AND(ISNUMBER(G12),ISNUMBER(H12)),H12-G12,"") | J12: =IFERROR(IF(INDEX(Roteiro!$T$5:$T$37,MATCH($A12&"|S",Roteiro!$AE$5:$AE$37,0))="","",INDEX(Roteiro!$T$5:$T$37,MATCH($A12&"|S",Roteiro!$AE$5:$AE$37,0))),"") | K12: =IFERROR(IF(INDEX(Roteiro!$T$5:$T$37,MATCH($A12&"|C",Roteiro!$AE$5:$AE$37,0))="","",INDEX(Roteiro!$T$5:$T$37,MATCH($A12&"|C",Roteiro!$AE$5:$AE$37,0))),"") | L12: =IF(AND(ISNUMBER(J12),ISNUMBER(K12)),K12-J12,"") | M12: =IFERROR(IF(INDEX(Roteiro!$Z$5:$Z$37,MATCH($A12&"|S",Roteiro!$AE$5:$AE$37,0))="","",INDEX(Roteiro!$Z$5:$Z$37,MATCH($A12&"|S",Roteiro!$AE$5:$AE$37,0))),"") | N12: =IFERROR(IF(INDEX(Roteiro!$Z$5:$Z$37,MATCH($A12&"|C",Roteiro!$AE$5:$AE$37,0))="","",INDEX(Roteiro!$Z$5:$Z$37,MATCH($A12&"|C",Roteiro!$AE$5:$AE$37,0))),"")
A13: =Roteiro!D8 -> IHC-2 | B13: =IFERROR(INDEX(Tarefas!$B$2:$B$20,MATCH($A13,Tarefas!$A$2:$A$20,0)),"") -> Núcleo | C13: =IFERROR(INDEX(Tarefas!$C$2:$C$20,MATCH($A13,Tarefas!$A$2:$A$20,0)),"") -> G1 | D13: =IFERROR(INDEX(Tarefas!$G$2:$G$20,MATCH($A13,Tarefas!$A$2:$A$20,0)),"") -> controle | E13: =IFERROR(IF(INDEX(Roteiro!$M$5:$M$37,MATCH($A13&"|S",Roteiro!$AE$5:$AE$37,0))="","",INDEX(Roteiro!$M$5:$M$37,MATCH($A13&"|S",Roteiro!$AE$5:$AE$37,0))),"") | F13: =IFERROR(IF(INDEX(Roteiro!$M$5:$M$37,MATCH($A13&"|C",Roteiro!$AE$5:$AE$37,0))="","",INDEX(Roteiro!$M$5:$M$37,MATCH($A13&"|C",Roteiro!$AE$5:$AE$37,0))),"") | G13: =IFERROR(IF(INDEX(Roteiro!$R$5:$R$37,MATCH($A13&"|S",Roteiro!$AE$5:$AE$37,0))="","",INDEX(Roteiro!$R$5:$R$37,MATCH($A13&"|S",Roteiro!$AE$5:$AE$37,0))),"") | H13: =IFERROR(IF(INDEX(Roteiro!$R$5:$R$37,MATCH($A13&"|C",Roteiro!$AE$5:$AE$37,0))="","",INDEX(Roteiro!$R$5:$R$37,MATCH($A13&"|C",Roteiro!$AE$5:$AE$37,0))),"") | I13: =IF(AND(ISNUMBER(G13),ISNUMBER(H13)),H13-G13,"") | J13: =IFERROR(IF(INDEX(Roteiro!$T$5:$T$37,MATCH($A13&"|S",Roteiro!$AE$5:$AE$37,0))="","",INDEX(Roteiro!$T$5:$T$37,MATCH($A13&"|S",Roteiro!$AE$5:$AE$37,0))),"") | K13: =IFERROR(IF(INDEX(Roteiro!$T$5:$T$37,MATCH($A13&"|C",Roteiro!$AE$5:$AE$37,0))="","",INDEX(Roteiro!$T$5:$T$37,MATCH($A13&"|C",Roteiro!$AE$5:$AE$37,0))),"") | L13: =IF(AND(ISNUMBER(J13),ISNUMBER(K13)),K13-J13,"") | M13: =IFERROR(IF(INDEX(Roteiro!$Z$5:$Z$37,MATCH($A13&"|S",Roteiro!$AE$5:$AE$37,0))="","",INDEX(Roteiro!$Z$5:$Z$37,MATCH($A13&"|S",Roteiro!$AE$5:$AE$37,0))),"") | N13: =IFERROR(IF(INDEX(Roteiro!$Z$5:$Z$37,MATCH($A13&"|C",Roteiro!$AE$5:$AE$37,0))="","",INDEX(Roteiro!$Z$5:$Z$37,MATCH($A13&"|C",Roteiro!$AE$5:$AE$37,0))),"")
A14: =Roteiro!D9 -> CSBC-2 | B14: =IFERROR(INDEX(Tarefas!$B$2:$B$20,MATCH($A14,Tarefas!$A$2:$A$20,0)),"") -> Núcleo | C14: =IFERROR(INDEX(Tarefas!$C$2:$C$20,MATCH($A14,Tarefas!$A$2:$A$20,0)),"") -> G1 | D14: =IFERROR(INDEX(Tarefas!$G$2:$G$20,MATCH($A14,Tarefas!$A$2:$A$20,0)),"") -> negativo | E14: =IFERROR(IF(INDEX(Roteiro!$M$5:$M$37,MATCH($A14&"|S",Roteiro!$AE$5:$AE$37,0))="","",INDEX(Roteiro!$M$5:$M$37,MATCH($A14&"|S",Roteiro!$AE$5:$AE$37,0))),"") | F14: =IFERROR(IF(INDEX(Roteiro!$M$5:$M$37,MATCH($A14&"|C",Roteiro!$AE$5:$AE$37,0))="","",INDEX(Roteiro!$M$5:$M$37,MATCH($A14&"|C",Roteiro!$AE$5:$AE$37,0))),"") | G14: =IFERROR(IF(INDEX(Roteiro!$R$5:$R$37,MATCH($A14&"|S",Roteiro!$AE$5:$AE$37,0))="","",INDEX(Roteiro!$R$5:$R$37,MATCH($A14&"|S",Roteiro!$AE$5:$AE$37,0))),"") | H14: =IFERROR(IF(INDEX(Roteiro!$R$5:$R$37,MATCH($A14&"|C",Roteiro!$AE$5:$AE$37,0))="","",INDEX(Roteiro!$R$5:$R$37,MATCH($A14&"|C",Roteiro!$AE$5:$AE$37,0))),"") | I14: =IF(AND(ISNUMBER(G14),ISNUMBER(H14)),H14-G14,"") | J14: =IFERROR(IF(INDEX(Roteiro!$T$5:$T$37,MATCH($A14&"|S",Roteiro!$AE$5:$AE$37,0))="","",INDEX(Roteiro!$T$5:$T$37,MATCH($A14&"|S",Roteiro!$AE$5:$AE$37,0))),"") | K14: =IFERROR(IF(INDEX(Roteiro!$T$5:$T$37,MATCH($A14&"|C",Roteiro!$AE$5:$AE$37,0))="","",INDEX(Roteiro!$T$5:$T$37,MATCH($A14&"|C",Roteiro!$AE$5:$AE$37,0))),"") | L14: =IF(AND(ISNUMBER(J14),ISNUMBER(K14)),K14-J14,"") | M14: =IFERROR(IF(INDEX(Roteiro!$Z$5:$Z$37,MATCH($A14&"|S",Roteiro!$AE$5:$AE$37,0))="","",INDEX(Roteiro!$Z$5:$Z$37,MATCH($A14&"|S",Roteiro!$AE$5:$AE$37,0))),"") | N14: =IFERROR(IF(INDEX(Roteiro!$Z$5:$Z$37,MATCH($A14&"|C",Roteiro!$AE$5:$AE$37,0))="","",INDEX(Roteiro!$Z$5:$Z$37,MATCH($A14&"|C",Roteiro!$AE$5:$AE$37,0))),"")
A15: =Roteiro!D12 -> SOL-2 | B15: =IFERROR(INDEX(Tarefas!$B$2:$B$20,MATCH($A15,Tarefas!$A$2:$A$20,0)),"") -> Núcleo | C15: =IFERROR(INDEX(Tarefas!$C$2:$C$20,MATCH($A15,Tarefas!$A$2:$A$20,0)),"") -> G2 | D15: =IFERROR(INDEX(Tarefas!$G$2:$G$20,MATCH($A15,Tarefas!$A$2:$A$20,0)),"") -> controle | E15: =IFERROR(IF(INDEX(Roteiro!$M$5:$M$37,MATCH($A15&"|S",Roteiro!$AE$5:$AE$37,0))="","",INDEX(Roteiro!$M$5:$M$37,MATCH($A15&"|S",Roteiro!$AE$5:$AE$37,0))),"") | F15: =IFERROR(IF(INDEX(Roteiro!$M$5:$M$37,MATCH($A15&"|C",Roteiro!$AE$5:$AE$37,0))="","",INDEX(Roteiro!$M$5:$M$37,MATCH($A15&"|C",Roteiro!$AE$5:$AE$37,0))),"") | G15: =IFERROR(IF(INDEX(Roteiro!$R$5:$R$37,MATCH($A15&"|S",Roteiro!$AE$5:$AE$37,0))="","",INDEX(Roteiro!$R$5:$R$37,MATCH($A15&"|S",Roteiro!$AE$5:$AE$37,0))),"") | H15: =IFERROR(IF(INDEX(Roteiro!$R$5:$R$37,MATCH($A15&"|C",Roteiro!$AE$5:$AE$37,0))="","",INDEX(Roteiro!$R$5:$R$37,MATCH($A15&"|C",Roteiro!$AE$5:$AE$37,0))),"") | I15: =IF(AND(ISNUMBER(G15),ISNUMBER(H15)),H15-G15,"") | J15: =IFERROR(IF(INDEX(Roteiro!$T$5:$T$37,MATCH($A15&"|S",Roteiro!$AE$5:$AE$37,0))="","",INDEX(Roteiro!$T$5:$T$37,MATCH($A15&"|S",Roteiro!$AE$5:$AE$37,0))),"") | K15: =IFERROR(IF(INDEX(Roteiro!$T$5:$T$37,MATCH($A15&"|C",Roteiro!$AE$5:$AE$37,0))="","",INDEX(Roteiro!$T$5:$T$37,MATCH($A15&"|C",Roteiro!$AE$5:$AE$37,0))),"") | L15: =IF(AND(ISNUMBER(J15),ISNUMBER(K15)),K15-J15,"") | M15: =IFERROR(IF(INDEX(Roteiro!$Z$5:$Z$37,MATCH($A15&"|S",Roteiro!$AE$5:$AE$37,0))="","",INDEX(Roteiro!$Z$5:$Z$37,MATCH($A15&"|S",Roteiro!$AE$5:$AE$37,0))),"") | N15: =IFERROR(IF(INDEX(Roteiro!$Z$5:$Z$37,MATCH($A15&"|C",Roteiro!$AE$5:$AE$37,0))="","",INDEX(Roteiro!$Z$5:$Z$37,MATCH($A15&"|C",Roteiro!$AE$5:$AE$37,0))),"")
